<?xml version="1.0" encoding="utf-8"?>
<!-- This URDF was automatically created by SolidWorks to URDF Exporter! Originally created by Stephen Brawner (brawner@gmail.com) 
     Commit Version: 1.6.0-4-g7f85cfe  Build Version: 1.6.7995.38578
     For more information, please see http://wiki.ros.org/sw_urdf_exporter -->
<robot
  name="8DOF_arm">
  <link
    name="base_link">
    <inertial>
      <origin
        xyz="7.01981621351124E-19 7.30091750501839E-18 0.0322476251952913"
        rpy="0 0 0" />
      <mass
        value="0.642659334578088" />
      <inertia
        ixx="0.00128323309798019"
        ixy="-5.79102308821978E-20"
        ixz="-1.24304284116364E-22"
        iyy="0.00128323309798019"
        iyz="9.24581334581879E-20"
        izz="0.0014380231118093" />
    </inertial>
    <visual>
      <origin
        xyz="0 0 0"
        rpy="0 0 0" />
      <geometry>
        <mesh
          filename="package://8DOF_arm/meshes/base_link.STL" />
      </geometry>
      <material
        name="">
        <color
          rgba="0.388235294117647 0.4 0.858823529411765 0.3" />
      </material>
    </visual>
    <collision>
      <origin
        xyz="0 0 0"
        rpy="0 0 0" />
      <geometry>
        <mesh
          filename="package://8DOF_arm/meshes/base_link.STL" />
      </geometry>
    </collision>
  </link>
  <link
    name="base_pin">
    <inertial>
      <origin
        xyz="-2.37440803027089E-15 0.0382952489796256 2.70140680659771E-16"
        rpy="0 0 0" />
      <mass
        value="0.0389102114458838" />
      <inertia
        ixx="2.07768422807742E-05"
        ixy="-6.89483633050152E-22"
        ixz="-8.37747101928375E-23"
        iyy="3.6324844996756E-06"
        iyz="2.21684945430942E-21"
        izz="2.09173954351496E-05" />
    </inertial>
    <visual>
      <origin
        xyz="0 0 0"
        rpy="0 0 0" />
      <geometry>
        <mesh
          filename="package://8DOF_arm/meshes/base_pin.STL" />
      </geometry>
      <material
        name="">
        <color
          rgba="0.388235294117647 0.4 0.858823529411765 0.3" />
      </material>
    </visual>
    <collision>
      <origin
        xyz="0 0 0"
        rpy="0 0 0" />
      <geometry>
        <mesh
          filename="package://8DOF_arm/meshes/base_pin.STL" />
      </geometry>
    </collision>
  </link>
  <joint
    name="base_pin"
    type="continuous">
    <origin
      xyz="0 0 0.0698499999999998"
      rpy="1.5707963267949 0 0" />
    <parent
      link="base_link" />
    <child
      link="base_pin" />
    <axis
      xyz="0 1 0" />
  </joint>
  <link
    name="first_link">
    <inertial>
      <origin
        xyz="-4.08292269085367E-09 -0.0550901722119836 2.09780265891524E-05"
        rpy="0 0 0" />
      <mass
        value="0.209590237829908" />
      <inertia
        ixx="0.000233815998884336"
        ixy="-6.41201289500509E-11"
        ixz="1.39710741372473E-09"
        iyy="9.29557212780078E-05"
        iyz="-6.93854355170575E-08"
        izz="0.000240744791848488" />
    </inertial>
    <visual>
      <origin
        xyz="0 0 0"
        rpy="0 0 0" />
      <geometry>
        <mesh
          filename="package://8DOF_arm/meshes/first_link.STL" />
      </geometry>
      <material
        name="">
        <color
          rgba="0.388235294117647 0.4 0.858823529411765 0.3" />
      </material>
    </visual>
    <collision>
      <origin
        xyz="0 0 0"
        rpy="0 0 0" />
      <geometry>
        <mesh
          filename="package://8DOF_arm/meshes/first_link.STL" />
      </geometry>
    </collision>
  </link>
  <joint
    name="first_link"
    type="continuous">
    <origin
      xyz="0 0.0635 0"
      rpy="1.5707963267949 1.5707963267949 0" />
    <parent
      link="base_pin" />
    <child
      link="first_link" />
    <axis
      xyz="1 0 0" />
  </joint>
  <link
    name="first_pin">
    <inertial>
      <origin
        xyz="0.025545876062429 -2.28292906086932E-15 0"
        rpy="0 0 0" />
      <mass
        value="0.0260398414768073" />
      <inertia
        ixx="2.59455351351942E-06"
        ixy="1.39685737648696E-21"
        ixz="-1.42378986672845E-21"
        iyy="7.10750707409668E-06"
        iyz="-2.42852814127492E-22"
        izz="6.96695391972137E-06" />
    </inertial>
    <visual>
      <origin
        xyz="0 0 0"
        rpy="0 0 0" />
      <geometry>
        <mesh
          filename="package://8DOF_arm/meshes/first_pin.STL" />
      </geometry>
      <material
        name="">
        <color
          rgba="0.388235294117647 0.4 0.858823529411765 0.3" />
      </material>
    </visual>
    <collision>
      <origin
        xyz="0 0 0"
        rpy="0 0 0" />
      <geometry>
        <mesh
          filename="package://8DOF_arm/meshes/first_pin.STL" />
      </geometry>
    </collision>
  </link>
  <joint
    name="first_pin"
    type="continuous">
    <origin
      xyz="0 -0.094412 0"
      rpy="0 0 -1.5708" />
    <parent
      link="first_link" />
    <child
      link="first_pin" />
    <axis
      xyz="1 0 0" />
  </joint>
  <link
    name="second_link">
    <inertial>
      <origin
        xyz="-4.08292010696858E-09 -0.0550901722119811 2.09780265891801E-05"
        rpy="0 0 0" />
      <mass
        value="0.209590237829908" />
      <inertia
        ixx="0.000233815998884336"
        ixy="-6.41201288853313E-11"
        ixz="1.39710741373865E-09"
        iyy="9.29557212780078E-05"
        iyz="-6.93854355169687E-08"
        izz="0.000240744791848488" />
    </inertial>
    <visual>
      <origin
        xyz="0 0 0"
        rpy="0 0 0" />
      <geometry>
        <mesh
          filename="package://8DOF_arm/meshes/second_link.STL" />
      </geometry>
      <material
        name="">
        <color
          rgba="0.388235294117647 0.4 0.858823529411765 0.3" />
      </material>
    </visual>
    <collision>
      <origin
        xyz="0 0 0"
        rpy="0 0 0" />
      <geometry>
        <mesh
          filename="package://8DOF_arm/meshes/second_link.STL" />
      </geometry>
    </collision>
  </link>
  <joint
    name="second_link"
    type="continuous">
    <origin
      xyz="0.0380999999999999 0 0"
      rpy="1.5707963267949 0 -1.5707963267949" />
    <parent
      link="first_pin" />
    <child
      link="second_link" />
    <axis
      xyz="1 0 0" />
  </joint>
  <link
    name="second_pin">
    <inertial>
      <origin
        xyz="0.025545876062429 0 -2.33354162788721E-15"
        rpy="0 0 0" />
      <mass
        value="0.0260398414768073" />
      <inertia
        ixx="2.59455351351943E-06"
        ixy="1.0021604189718E-21"
        ixz="-2.85175925370698E-22"
        iyy="7.10750707409667E-06"
        iyz="5.83761034000549E-23"
        izz="6.96695391972135E-06" />
    </inertial>
    <visual>
      <origin
        xyz="0 0 0"
        rpy="0 0 0" />
      <geometry>
        <mesh
          filename="package://8DOF_arm/meshes/second_pin.STL" />
      </geometry>
      <material
        name="">
        <color
          rgba="0.388235294117647 0.4 0.858823529411765 0.3" />
      </material>
    </visual>
    <collision>
      <origin
        xyz="0 0 0"
        rpy="0 0 0" />
      <geometry>
        <mesh
          filename="package://8DOF_arm/meshes/second_pin.STL" />
      </geometry>
    </collision>
  </link>
  <joint
    name="second_pin"
    type="continuous">
    <origin
      xyz="0 -0.094412 0"
      rpy="1.5708 0 -1.5708" />
    <parent
      link="second_link" />
    <child
      link="second_pin" />
    <axis
      xyz="1 0 0" />
  </joint>
  <link
    name="third_link">
    <inertial>
      <origin
        xyz="-4.0829E-09 0.05509 -2.0978E-05"
        rpy="0 0 0" />
      <mass
        value="0.20959" />
      <inertia
        ixx="0.00023382"
        ixy="6.412E-11"
        ixz="-1.3971E-09"
        iyy="9.2956E-05"
        iyz="-6.9385E-08"
        izz="0.00024074" />
    </inertial>
    <visual>
      <origin
        xyz="0 0 0"
        rpy="0 0 0" />
      <geometry>
        <mesh
          filename="package://8DOF_arm/meshes/third_link.STL" />
      </geometry>
      <material
        name="">
        <color
          rgba="0.38824 0.4 0.85882 0.3" />
      </material>
    </visual>
    <collision>
      <origin
        xyz="0 0 0"
        rpy="0 0 0" />
      <geometry>
        <mesh
          filename="package://8DOF_arm/meshes/third_link.STL" />
      </geometry>
    </collision>
  </link>
  <joint
    name="third_link"
    type="continuous">
    <origin
      xyz="0.0381 0 0"
      rpy="1.5707963267949 0 -1.5707963267949" />
    <parent
      link="second_pin" />
    <child
      link="third_link" />
    <axis
      xyz="1 0 0" />
  </joint>
  <link
    name="tennis_pin">
    <inertial>
      <origin
        xyz="0 0.033201 -2.7756E-17"
        rpy="0 0 0" />
      <mass
        value="0.035752" />
      <inertia
        ixx="1.378E-05"
        ixy="1.1705E-21"
        ixz="6.5644E-22"
        iyy="8.2428E-06"
        iyz="3.6051E-21"
        izz="1.8417E-05" />
    </inertial>
    <visual>
      <origin
        xyz="0 0 0"
        rpy="0 0 0" />
      <geometry>
        <mesh
          filename="package://8DOF_arm/meshes/tennis_pin.STL" />
      </geometry>
      <material
        name="">
        <color
          rgba="0.38824 0.4 0.85882 0.3" />
      </material>
    </visual>
    <collision>
      <origin
        xyz="0 0 0"
        rpy="0 0 0" />
      <geometry>
        <mesh
          filename="package://8DOF_arm/meshes/tennis_pin.STL" />
      </geometry>
    </collision>
  </link>
  <joint
    name="tennis_pin"
    type="continuous">
    <origin
      xyz="0 0.094412 0"
      rpy="0 1.5708 0" />
    <parent
      link="third_link" />
    <child
      link="tennis_pin" />
    <axis
      xyz="0 1 0" />
  </joint>
  <link
    name="tennis_racket">
    <inertial>
      <origin
        xyz="0.366359357987308 -1.49720355002714E-08 0.0155192883141906"
        rpy="0 0 0" />
      <mass
        value="2.70157890421177" />
      <inertia
        ixx="0.0145954644076415"
        ixy="-9.92588746263243E-09"
        ixz="-0.00108274864307061"
        iyy="0.059825373112049"
        iyz="-1.62234246216851E-09"
        izz="0.0455197680924056" />
    </inertial>
    <visual>
      <origin
        xyz="0 0 0"
        rpy="0 0 0" />
      <geometry>
        <mesh
          filename="package://8DOF_arm/meshes/tennis_racket.STL" />
      </geometry>
      <material
        name="">
        <color
          rgba="0.286274509803922 0.662745098039216 0.329411764705882 1" />
      </material>
    </visual>
    <collision>
      <origin
        xyz="0 0 0"
        rpy="0 0 0" />
      <geometry>
        <mesh
          filename="package://8DOF_arm/meshes/tennis_racket.STL" />
      </geometry>
    </collision>
  </link>
  <joint
    name="tennis_racket"
    type="continuous">
    <origin
      xyz="0 0.0571499999999999 0"
      rpy="0 -0.661454620295037 1.5707963267949" />
    <parent
      link="tennis_pin" />
    <child
      link="tennis_racket" />
    <axis
      xyz="0 1 0" />
  </joint>
</robot>